Workbook
Name Fluxo: OFFSET([1]Cad_Natureza!$G$4,0,0,COUNTA([1]Cad_Natureza!$G$4:$G$102))
Name Fluxo: OFFSET(Cad_Natureza!$G$4,0,0,COUNTA(Cad_Natureza!$G$4:$G$102))
Name Lista_CRs: OFFSET([1]Cad_Natureza!$C$4,0,0,COUNTA([1]Cad_Natureza!$C$5:$C$52)+3)
Name Lista_CRs: OFFSET(Cad_Natureza!$C$4,0,0,COUNTA(Cad_Natureza!$C$5:$C$52)+3)
Name Lista_Socios: OFFSET([1]Cad_Natureza!$E$4,0,0,COUNTA([1]Cad_Natureza!$E$4:$E$102))
Name Lista_Socios: OFFSET(Cad_Natureza!$E$4,0,0,COUNTA(Cad_Natureza!$E$4:$E$102))

Sheet Cad_Natureza
B3: Natureza | C3: Descrição CR | E3: Entidade | G3: Fluxo
B4: - | C4: TODOS CRs | E4: MCS | F4: =OFFSET(Cad_Natureza!$E$4,0,0,COUNTA(Cad_Natureza!$E$4:$E$102)) -> MCS | G4: REAL | H4: =OFFSET(Cad_Natureza!$G$4,0,0,COUNTA(Cad_Natureza!$G$4:$G$102)) -> REAL
B5: REC1 | C5: CPF - Remun. Salário / Pró-Labore | G5: PREVISTO | H5: =OFFSET(Cad_Natureza!$G$4,0,0,COUNTA(Cad_Natureza!$G$4:$G$102)) -> PREVISTO
B6: REC2 | C6: CPF - Ajuda de custo - Combustível
B7: REC3 | C7: CPF - Ajuda de custo - Refeição
B8: REC4 | C8: CPF - Transf. Da conta PJ para a conta PF
B9: REC5 | C9: CPF - Outras receitas
B10: REC6 | C10: CPF - Pensão - Outras receitas
B11: REC7 | C11: CPF - Rec. Financeiras - Empréstimos
B13: OPF1 | C13: CPF - Desp. Alimentação / Refeição
B14: OPF2 | C14: CPF - Desp. Transporte / Combustível
B15: DESP1 | C15: CPF - Desp. Cartão de crédito
B16: DESP2 | C16: CPF - Desp. Telefone / Internet
B17: DESP3 | C17: CPF - Desp. com veículo - Manut. / Gastos
B18: DESP4 | C18: CPF - Desp. Moradia
... B53: X | C53: X

Sheet 2025
K1: =SUBTOTAL(9,K3:K940) -> 6120.48 | L1: -1
B2: EMPRESA | C2: x | D2: Natureza | E2: Descrição | F2: Centro de Resultado | G2: Entidade | H2: Data real | I2: Data prevista | J2: Observações | K2: Total | L2: Saldo banco | M2: x | N2: Empresa & CR | O2: Concat 2 | P2: Concat 3 | Q2: Concat 3 | R2: Empresa & Natureza | S2: x | T2: DATA REAL | U2: DATA PREVISTA | V2: X
B3: MCS | D3: =INDEX(Cad_Natureza!$B$3:$C$52,MATCH('2025'!F3,Cad_Natureza!$C$3:$C$52,0),MATCH('2025'!D$2,Cad_Natureza!$B$3:$C$3,0)) -> FIN2 | E3: JUROS EXCESSO LIM CONTA | F3: CPF - Desp. Financeiras - Juros / Tarifas | G3: MCS | H3: 45659 | J3: Juros / Tarifas bancárias | K3: -24.15 | L3: -5921.44 | N3: =B3&D3&F3 -> MCSFIN2CPF - Desp. Financeiras - Juros / Tarifas | O3: =D3&F3 -> FIN2CPF - Desp. Financeiras - Juros / Tarifas | P3: ="MCS"&D3&F3 -> MCSFIN2CPF - Desp. Financeiras - Juros / Tarifas | Q3: ="MCS"&D3 -> MCSFIN2 | R3: =B3&D3 -> MCSFIN2 | T3: =(1&"/"&MONTH(H3)&"/"&YEAR(H3))*1 -> 45658 | U3: =IF(I3="","",(1&"/"&MONTH(I3)&"/"&YEAR(I3))*1) | V3: Z
B4: MCS | D4: =INDEX(Cad_Natureza!$B$3:$C$52,MATCH('2025'!F4,Cad_Natureza!$C$3:$C$52,0),MATCH('2025'!D$2,Cad_Natureza!$B$3:$C$3,0)) -> FIN2 | E4: JUROS EXCESSO LIM CONTA | F4: CPF - Desp. Financeiras - Juros / Tarifas | G4: MCS | H4: 45659 | J4: Juros / Tarifas bancárias | K4: -17.09 | L4: -5938.53 | N4: =B4&D4&F4 -> MCSFIN2CPF - Desp. Financeiras - Juros / Tarifas | O4: =D4&F4 -> FIN2CPF - Desp. Financeiras - Juros / Tarifas | P4: ="MCS"&D4&F4 -> MCSFIN2CPF - Desp. Financeiras - Juros / Tarifas | Q4: ="MCS"&D4 -> MCSFIN2 | R4: =B4&D4 -> MCSFIN2 | T4: =(1&"/"&MONTH(H4)&"/"&YEAR(H4))*1 -> 45658 | U4: =IF(I4="","",(1&"/"&MONTH(I4)&"/"&YEAR(I4))*1) | V4: Z
B5: MCS | D5: =INDEX(Cad_Natureza!$B$3:$C$52,MATCH('2025'!F5,Cad_Natureza!$C$3:$C$52,0),MATCH('2025'!D$2,Cad_Natureza!$B$3:$C$3,0)) -> FIN2 | E5: IOF | F5: CPF - Desp. Financeiras - Juros / Tarifas | G5: MCS | H5: 45660 | J5: Impostos | K5: -17.02 | L5: -5955.55 | N5: =B5&D5&F5 -> MCSFIN2CPF - Desp. Financeiras - Juros / Tarifas | O5: =D5&F5 -> FIN2CPF - Desp. Financeiras - Juros / Tarifas | P5: ="MCS"&D5&F5 -> MCSFIN2CPF - Desp. Financeiras - Juros / Tarifas | Q5: ="MCS"&D5 -> MCSFIN2 | R5: =B5&D5 -> MCSFIN2 | T5: =(1&"/"&MONTH(H5)&"/"&YEAR(H5))*1 -> 45658 | U5: =IF(I5="","",(1&"/"&MONTH(I5)&"/"&YEAR(I5))*1) | V5: Z
B6: MCS | D6: =INDEX(Cad_Natureza!$B$3:$C$52,MATCH('2025'!F6,Cad_Natureza!$C$3:$C$52,0),MATCH('2025'!D$2,Cad_Natureza!$B$3:$C$3,0)) -> FIN1 | E6: CREDIARIO AUTOM 01/07 | F6: CPF - Desp. Financeiras - Empréstimos | G6: MCS | H6: 45665 | J6: Empréstimo cheque especial | K6: -127.18 | L6: -6082.73 | N6: =B6&D6&F6 -> MCSFIN1CPF - Desp. Financeiras - Empréstimos | O6: =D6&F6 -> FIN1CPF - Desp. Financeiras - Empréstimos | P6: ="MCS"&D6&F6 -> MCSFIN1CPF - Desp. Financeiras - Empréstimos | Q6: ="MCS"&D6 -> MCSFIN1 | R6: =B6&D6 -> MCSFIN1 | T6: =(1&"/"&MONTH(H6)&"/"&YEAR(H6))*1 -> 45658 | U6: =IF(I6="","",(1&"/"&MONTH(I6)&"/"&YEAR(I6))*1) | V6: Z
B7: MCS | D7: =INDEX(Cad_Natureza!$B$3:$C$52,MATCH('2025'!F7,Cad_Natureza!$C$3:$C$52,0),MATCH('2025'!D$2,Cad_Natureza!$B$3:$C$3,0)) -> DESP1 | E7: INT PAG TIT BANCO 237 | F7: CPF - Desp. Cartão de crédito | G7: MCS | H7: 45665 | J7: Pagamento de valor mínimo - Riachuelo | K7: -5.9 | L7: -6088.63 | N7: =B7&D7&F7 -> MCSDESP1CPF - Desp. Cartão de crédito | O7: =D7&F7 -> DESP1CPF - Desp. Cartão de crédito | P7: ="MCS"&D7&F7 -> MCSDESP1CPF - Desp. Cartão de crédito | Q7: ="MCS"&D7 -> MCSDESP1 | R7: =B7&D7 -> MCSDESP1 | T7: =(1&"/"&MONTH(H7)&"/"&YEAR(H7))*1 -> 45658 | U7: =IF(I7="","",(1&"/"&MONTH(I7)&"/"&YEAR(I7))*1) | V7: Z
B8: MCS | D8: =INDEX(Cad_Natureza!$B$3:$C$52,MATCH('2025'!F8,Cad_Natureza!$C$3:$C$52,0),MATCH('2025'!D$2,Cad_Natureza!$B$3:$C$3,0)) -> REC4 | E8: PIX TRANSF MCS SER08/01 | F8: CPF - Transf. Da conta PJ para a conta PF | G8: MCS | H8: 45665 | J8: Transferência entre contas | K8: 1000 | L8: -5088.63 | N8: =B8&D8&F8 -> MCSREC4CPF - Transf. Da conta PJ para a conta PF | O8: =D8&F8 -> REC4CPF - Transf. Da conta PJ para a conta PF | P8: ="MCS"&D8&F8 -> MCSREC4CPF - Transf. Da conta PJ para a conta PF | Q8: ="MCS"&D8 -> MCSREC4 | R8: =B8&D8 -> MCSREC4 | T8: =(1&"/"&MONTH(H8)&"/"&YEAR(H8))*1 -> 45658 | U8: =IF(I8="","",(1&"/"&MONTH(I8)&"/"&YEAR(I8))*1) | V8: Z
B9: MCS | D9: =INDEX(Cad_Natureza!$B$3:$C$52,MATCH('2025'!F9,Cad_Natureza!$C$3:$C$52,0),MATCH('2025'!D$2,Cad_Natureza!$B$3:$C$3,0)) -> PENS5 | E9: INT /BRK GOIA 4077325407 | F9: CPF - Pensão - Água | G9: MCS | H9: 45665 | J9: Pensão - fatura de água | K9: -205.22 | L9: -5293.85 | N9: =B9&D9&F9 -> MCSPENS5CPF - Pensão - Água | O9: =D9&F9 -> PENS5CPF - Pensão - Água | P9: ="MCS"&D9&F9 -> MCSPENS5CPF - Pensão - Água | Q9: ="MCS"&D9 -> MCSPENS5 | R9: =B9&D9 -> MCSPENS5 | T9: =(1&"/"&MONTH(H9)&"/"&YEAR(H9))*1 -> 45658 | U9: =IF(I9="","",(1&"/"&MONTH(I9)&"/"&YEAR(I9))*1) | V9: X
B10: MCS | D10: =INDEX(Cad_Natureza!$B$3:$C$52,MATCH('2025'!F10,Cad_Natureza!$C$3:$C$52,0),MATCH('2025'!D$2,Cad_Natureza!$B$3:$C$3,0)) -> PENS2 | E10: INT PAG TIT 338563315000 | F10: CPF - Pensão - Energia | G10: MCS | H10: 45665 | J10: Pensão - Conta de energia ref. 11/2024 | K10: -277.69 | L10: -5571.54 | N10: =B10&D10&F10 -> MCSPENS2CPF - Pensão - Energia | O10: =D10&F10 -> PENS2CPF - Pensão - Energia | P10: ="MCS"&D10&F10 -> MCSPENS2CPF - Pensão - Energia | Q10: ="MCS"&D10 -> MCSPENS2 | R10: =B10&D10 -> MCSPENS2 | T10: =(1&"/"&MONTH(H10)&"/"&YEAR(H10))*1 -> 45658 | U10: =IF(I10="","",(1&"/"&MONTH(I10)&"/"&YEAR(I10))*1) | V10: X
B11: MCS | D11: =INDEX(Cad_Natureza!$B$3:$C$52,MATCH('2025'!F11,Cad_Natureza!$C$3:$C$52,0),MATCH('2025'!D$2,Cad_Natureza!$B$3:$C$3,0)) -> FIN3 | E11: RENEGOCIACAO ITAU | F11: CPF - Desp. Financeiras - Empréstimos bancários | G11: MCS | H11: 45665 | J11: Renegociação cheque especial | K11: 6270.89 | L11: 699.35 | N11: =B11&D11&F11 -> MCSFIN3CPF - Desp. Financeiras - Empréstimos bancários | O11: =D11&F11 -> FIN3CPF - Desp. Financeiras - Empréstimos bancários | P11: ="MCS"&D11&F11 -> MCSFIN3CPF - Desp. Financeiras - Empréstimos bancários | Q11: ="MCS"&D11 -> MCSFIN3 | R11: =B11&D11 -> MCSFIN3 | T11: =(1&"/"&MONTH(H11)&"/"&YEAR(H11))*1 -> 45658 | U11: =IF(I11="","",(1&"/"&MONTH(I11)&"/"&YEAR(I11))*1) | V11: Z
B12: MCS | D12: =INDEX(Cad_Natureza!$B$3:$C$52,MATCH('2025'!F12,Cad_Natureza!$C$3:$C$52,0),MATCH('2025'!D$2,Cad_Natureza!$B$3:$C$3,0)) -> TRI1 | E12: TAR PACOTE ITAU DEZ/24 | F12: CPF - Desp. Impostos e Obrigações | G12: MCS | H12: 45665 | J12: Tarifas bancárias | K12: -28 | L12: 671.35 | N12: =B12&D12&F12 -> MCSTRI1CPF - Desp. Impostos e Obrigações | O12: =D12&F12 -> TRI1CPF - Desp. Impostos e Obrigações | P12: ="MCS"&D12&F12 -> MCSTRI1CPF - Desp. Impostos e Obrigações | Q12: ="MCS"&D12 -> MCSTRI1 | R12: =B12&D12 -> MCSTRI1 | T12: =(1&"/"&MONTH(H12)&"/"&YEAR(H12))*1 -> 45658 | U12: =IF(I12="","",(1&"/"&MONTH(I12)&"/"&YEAR(I12))*1) | V12: Z
B13: MCS | D13: =INDEX(Cad_Natureza!$B$3:$C$52,MATCH('2025'!F13,Cad_Natureza!$C$3:$C$52,0),MATCH('2025'!D$2,Cad_Natureza!$B$3:$C$3,0)) -> OPF2 | E13: RSCSS POSTO TALISM0901 POSTO TALISMA | F13: CPF - Desp. Transporte / Combustível | G13: MCS | H13: 45666 | J13: Combustível | K13: -50 | L13: 621.35 | N13: =B13&D13&F13 -> MCSOPF2CPF - Desp. Transporte / Combustível | O13: =D13&F13 -> OPF2CPF - Desp. Transporte / Combustível | P13: ="MCS"&D13&F13 -> MCSOPF2CPF - Desp. Transporte / Combustível | Q13: ="MCS"&D13 -> MCSOPF2 | R13: =B13&D13 -> MCSOPF2 | T13: =(1&"/"&MONTH(H13)&"/"&YEAR(H13))*1 -> 45658 | U13: =IF(I13="","",(1&"/"&MONTH(I13)&"/"&YEAR(I13))*1) | V13: Z
B14: MCS | D14: =INDEX(Cad_Natureza!$B$3:$C$52,MATCH('2025'!F14,Cad_Natureza!$C$3:$C$52,0),MATCH('2025'!D$2,Cad_Natureza!$B$3:$C$3,0)) -> PENS9 | E14: PIX TRANSF Dieyla 09/01 | F14: CPF - Pensão - Outros Gastos | G14: MCS | H14: 45666 | J14: Pensão - Gastos diversos | K14: -10 | L14: 611.35 | N14: =B14&D14&F14 -> MCSPENS9CPF - Pensão - Outros Gastos | O14: =D14&F14 -> PENS9CPF - Pensão - Outros Gastos | P14: ="MCS"&D14&F14 -> MCSPENS9CPF - Pensão - Outros Gastos | Q14: ="MCS"&D14 -> MCSPENS9 | R14: =B14&D14 -> MCSPENS9 | T14: =(1&"/"&MONTH(H14)&"/"&YEAR(H14))*1 -> 45658 | U14: =IF(I14="","",(1&"/"&MONTH(I14)&"/"&YEAR(I14))*1) | V14: X
... B442: MCS | D442: =INDEX(Cad_Natureza!$B$3:$C$52,MATCH('2025'!F442,Cad_Natureza!$C$3:$C$52,0),MATCH('2025'!D$2,Cad_Natureza!$B$3:$C$3,0)) -> PENS1 | E442: PIX TRANSF JOAO DE10/06 | F442: CPF - Pensão - Aluguel | G442: MCS | H442: 45818 | J442: Pensão - Aluguel ref. 06/2025 | K442: -700 | L442: 741.72 | N442: =B442&D442&F442 -> MCSPENS1CPF - Pensão - Aluguel | O442: =D442&F442 -> PENS1CPF - Pensão - Aluguel | P442: ="MCS"&D442&F442 -> MCSPENS1CPF - Pensão - Aluguel | Q442: ="MCS"&D442 -> MCSPENS1 | R442: =B442&D442 -> MCSPENS1 | T442: =(1&"/"&MONTH(H442)&"/"&YEAR(H442))*1 -> 45809 | U442: =IF(I442="","",(1&"/"&MONTH(I442)&"/"&YEAR(I442))*1) | V442: X
B443: MCS | D443: =INDEX(Cad_Natureza!$B$3:$C$52,MATCH('2025'!F443,Cad_Natureza!$C$3:$C$52,0),MATCH('2025'!D$2,Cad_Natureza!$B$3:$C$3,0)) -> DESP1 | E443: Cartão Riachuelo - seguro ref. 03/2025 | F443: CPF - Desp. Cartão de crédito | G443: MCS | H443: 45818 | J443: seguro ref. 03/2025 | K443: -5.9 | L443: =L442+K443 -> 735.82 | N443: =B443&D443&F443 -> MCSDESP1CPF - Desp. Cartão de crédito | O443: =D443&F443 -> DESP1CPF - Desp. Cartão de crédito | P443: ="MCS"&D443&F443 -> MCSDESP1CPF - Desp. Cartão de crédito | Q443: ="MCS"&D443 -> MCSDESP1 | R443: =B443&D443 -> MCSDESP1 | T443: =(1&"/"&MONTH(H443)&"/"&YEAR(H443))*1 -> 45809 | U443: =IF(I443="","",(1&"/"&MONTH(I443)&"/"&YEAR(I443))*1) | V443: Z
B444: MCS | D444: =INDEX(Cad_Natureza!$B$3:$C$52,MATCH('2025'!F444,Cad_Natureza!$C$3:$C$52,0),MATCH('2025'!D$2,Cad_Natureza!$B$3:$C$3,0)) -> GAST2 | E444: RSCSS ALTAS HORAS 1106 | F444: CPF - Desp. Lazer e Entretenimento - Cigarro | G444: MCS | H444: 45819 | J444: Palheiro | K444: -32 | L444: =L443+K444 -> 703.82 | N444: =B444&D444&F444 -> MCSGAST2CPF - Desp. Lazer e Entretenimento - Cigarro | O444: =D444&F444 -> GAST2CPF - Desp. Lazer e Entretenimento - Cigarro | P444: ="MCS"&D444&F444 -> MCSGAST2CPF - Desp. Lazer e Entretenimento - Cigarro | Q444: ="MCS"&D444 -> MCSGAST2 | R444: =B444&D444 -> MCSGAST2 | T444: =(1&"/"&MONTH(H444)&"/"&YEAR(H444))*1 -> 45809 | U444: =IF(I444="","",(1&"/"&MONTH(I444)&"/"&YEAR(I444))*1) | V444: Z
B445: MCS | D445: =INDEX(Cad_Natureza!$B$3:$C$52,MATCH('2025'!F445,Cad_Natureza!$C$3:$C$52,0),MATCH('2025'!D$2,Cad_Natureza!$B$3:$C$3,0)) -> GAST1 | E445: RSCSS DISTRIBUIDOR1206 - BAR DO CEARÁ | F445: CPF - Desp. Lazer e Entretenimento - Bares | G445: MCS | H445: 45820 | J445: Bares - Com a Débora | K445: -78.5 | L445: =L444+K445 -> 625.32 | N445: =B445&D445&F445 -> MCSGAST1CPF - Desp. Lazer e Entretenimento - Bares | O445: =D445&F445 -> GAST1CPF - Desp. Lazer e Entretenimento - Bares | P445: ="MCS"&D445&F445 -> MCSGAST1CPF - Desp. Lazer e Entretenimento - Bares | Q445: ="MCS"&D445 -> MCSGAST1 | R445: =B445&D445 -> MCSGAST1 | T445: =(1&"/"&MONTH(H445)&"/"&YEAR(H445))*1 -> 45809 | U445: =IF(I445="","",(1&"/"&MONTH(I445)&"/"&YEAR(I445))*1) | V445: Z
B446: MCS | D446: =INDEX(Cad_Natureza!$B$3:$C$52,MATCH('2025'!F446,Cad_Natureza!$C$3:$C$52,0),MATCH('2025'!D$2,Cad_Natureza!$B$3:$C$3,0)) -> OPF2 | E446: RSCSS AUTO POSTO D1206 | F446: CPF - Desp. Transporte / Combustível | G446: MCS | H446: 45820 | J446: Combustível | K446: -50 | L446: =L445+K446 -> 575.32 | N446: =B446&D446&F446 -> MCSOPF2CPF - Desp. Transporte / Combustível | O446: =D446&F446 -> OPF2CPF - Desp. Transporte / Combustível | P446: ="MCS"&D446&F446 -> MCSOPF2CPF - Desp. Transporte / Combustível | Q446: ="MCS"&D446 -> MCSOPF2 | R446: =B446&D446 -> MCSOPF2 | T446: =(1&"/"&MONTH(H446)&"/"&YEAR(H446))*1 -> 45809 | U446: =IF(I446="","",(1&"/"&MONTH(I446)&"/"&YEAR(I446))*1) | V446: Z
B447: MCS | D447: =INDEX(Cad_Natureza!$B$3:$C$52,MATCH('2025'!F447,Cad_Natureza!$C$3:$C$52,0),MATCH('2025'!D$2,Cad_Natureza!$B$3:$C$3,0)) -> GAST1 | E447: RSCSS ORIENTE BEBI1206 | F447: CPF - Desp. Lazer e Entretenimento - Bares | G447: MCS | H447: 45820 | J447: Bares (antes da meia noite) - Com a Débora | K447: -13 | L447: =L446+K447 -> 562.32 | N447: =B447&D447&F447 -> MCSGAST1CPF - Desp. Lazer e Entretenimento - Bares | O447: =D447&F447 -> GAST1CPF - Desp. Lazer e Entretenimento - Bares | P447: ="MCS"&D447&F447 -> MCSGAST1CPF - Desp. Lazer e Entretenimento - Bares | Q447: ="MCS"&D447 -> MCSGAST1 | R447: =B447&D447 -> MCSGAST1 | T447: =(1&"/"&MONTH(H447)&"/"&YEAR(H447))*1 -> 45809 | U447: =IF(I447="","",(1&"/"&MONTH(I447)&"/"&YEAR(I447))*1) | V447: Z
B448: MCS | D448: =INDEX(Cad_Natureza!$B$3:$C$52,MATCH('2025'!F448,Cad_Natureza!$C$3:$C$52,0),MATCH('2025'!D$2,Cad_Natureza!$B$3:$C$3,0)) -> GAST1 | E448: RSCSS ORIENTE BEBI1206 | F448: CPF - Desp. Lazer e Entretenimento - Bares | G448: MCS | H448: 45820 | J448: Bares (antes da meia noite) - Com a Débora | K448: -12 | L448: =L447+K448 -> 550.32 | N448: =B448&D448&F448 -> MCSGAST1CPF - Desp. Lazer e Entretenimento - Bares | O448: =D448&F448 -> GAST1CPF - Desp. Lazer e Entretenimento - Bares | P448: ="MCS"&D448&F448 -> MCSGAST1CPF - Desp. Lazer e Entretenimento - Bares | Q448: ="MCS"&D448 -> MCSGAST1 | R448: =B448&D448 -> MCSGAST1 | T448: =(1&"/"&MONTH(H448)&"/"&YEAR(H448))*1 -> 45809 | U448: =IF(I448="","",(1&"/"&MONTH(I448)&"/"&YEAR(I448))*1) | V448: Z
B449: MCS | D449: =INDEX(Cad_Natureza!$B$3:$C$52,MATCH('2025'!F449,Cad_Natureza!$C$3:$C$52,0),MATCH('2025'!D$2,Cad_Natureza!$B$3:$C$3,0)) -> GAST1 | E449: RSCSS ORIENTE BEBI1206 | F449: CPF - Desp. Lazer e Entretenimento - Bares | G449: MCS | H449: 45820 | J449: Bares (antes da meia noite) - Com a Débora | K449: -19 | L449: =L448+K449 -> 531.32 | N449: =B449&D449&F449 -> MCSGAST1CPF - Desp. Lazer e Entretenimento - Bares | O449: =D449&F449 -> GAST1CPF - Desp. Lazer e Entretenimento - Bares | P449: ="MCS"&D449&F449 -> MCSGAST1CPF - Desp. Lazer e Entretenimento - Bares | Q449: ="MCS"&D449 -> MCSGAST1 | R449: =B449&D449 -> MCSGAST1 | T449: =(1&"/"&MONTH(H449)&"/"&YEAR(H449))*1 -> 45809 | U449: =IF(I449="","",(1&"/"&MONTH(I449)&"/"&YEAR(I449))*1) | V449: Z
B450: MCS | D450: =INDEX(Cad_Natureza!$B$3:$C$52,MATCH('2025'!F450,Cad_Natureza!$C$3:$C$52,0),MATCH('2025'!D$2,Cad_Natureza!$B$3:$C$3,0)) -> GAST1 | E450: RSCSS ORIENTE BEBI1306 | F450: CPF - Desp. Lazer e Entretenimento - Bares | G450: MCS | H450: 45821 | J450: Bares (depois da meia noite) - Com a Débora | K450: -14 | L450: =L449+K450 -> 517.32 | N450: =B450&D450&F450 -> MCSGAST1CPF - Desp. Lazer e Entretenimento - Bares | O450: =D450&F450 -> GAST1CPF - Desp. Lazer e Entretenimento - Bares | P450: ="MCS"&D450&F450 -> MCSGAST1CPF - Desp. Lazer e Entretenimento - Bares | Q450: ="MCS"&D450 -> MCSGAST1 | R450: =B450&D450 -> MCSGAST1 | T450: =(1&"/"&MONTH(H450)&"/"&YEAR(H450))*1 -> 45809 | U450: =IF(I450="","",(1&"/"&MONTH(I450)&"/"&YEAR(I450))*1) | V450: Z
B451: MCS | D451: =INDEX(Cad_Natureza!$B$3:$C$52,MATCH('2025'!F451,Cad_Natureza!$C$3:$C$52,0),MATCH('2025'!D$2,Cad_Natureza!$B$3:$C$3,0)) -> FIN3 | E451: RENEGOCIACAO ITAU 06/18 | F451: CPF - Desp. Financeiras - Empréstimos bancários | G451: MCS | H451: 45821 | J451: Renegociação cheque especial | K451: -538.03 | L451: =L450+K451 -> -20.71 | N451: =B451&D451&F451 -> MCSFIN3CPF - Desp. Financeiras - Empréstimos bancários | O451: =D451&F451 -> FIN3CPF - Desp. Financeiras - Empréstimos bancários | P451: ="MCS"&D451&F451 -> MCSFIN3CPF - Desp. Financeiras - Empréstimos bancários | Q451: ="MCS"&D451 -> MCSFIN3 | R451: =B451&D451 -> MCSFIN3 | T451: =(1&"/"&MONTH(H451)&"/"&YEAR(H451))*1 -> 45809 | U451: =IF(I451="","",(1&"/"&MONTH(I451)&"/"&YEAR(I451))*1) | V451: Z
B452: MCS | D452: =INDEX(Cad_Natureza!$B$3:$C$52,MATCH('2025'!F452,Cad_Natureza!$C$3:$C$52,0),MATCH('2025'!D$2,Cad_Natureza!$B$3:$C$3,0)) -> REC5 | E452: PIX TRANSF DEBORAH13/06 | F452: CPF - Outras receitas | G452: MCS | H452: 45821 | J452: Reembolso gasolina | K452: 30 | L452: =L451+K452 -> 9.29 | N452: =B452&D452&F452 -> MCSREC5CPF - Outras receitas | O452: =D452&F452 -> REC5CPF - Outras receitas | P452: ="MCS"&D452&F452 -> MCSREC5CPF - Outras receitas | Q452: ="MCS"&D452 -> MCSREC5 | R452: =B452&D452 -> MCSREC5 | T452: =(1&"/"&MONTH(H452)&"/"&YEAR(H452))*1 -> 45809 | U452: =IF(I452="","",(1&"/"&MONTH(I452)&"/"&YEAR(I452))*1) | V452: Z
B453: MCS | D453: =INDEX(Cad_Natureza!$B$3:$C$52,MATCH('2025'!F453,Cad_Natureza!$C$3:$C$52,0),MATCH('2025'!D$2,Cad_Natureza!$B$3:$C$3,0)) -> OPF2 | E453: RSCSS AUTO POSTO R1306 | F453: CPF - Desp. Transporte / Combustível | G453: MCS | H453: 45821 | J453: Combustível - perto da rodoviária de Ap. Gyn buscar a Débora | K453: -30 | L453: =L452+K453 -> -20.71 | N453: =B453&D453&F453 -> MCSOPF2CPF - Desp. Transporte / Combustível | O453: =D453&F453 -> OPF2CPF - Desp. Transporte / Combustível | P453: ="MCS"&D453&F453 -> MCSOPF2CPF - Desp. Transporte / Combustível | Q453: ="MCS"&D453 -> MCSOPF2 | R453: =B453&D453 -> MCSOPF2 | T453: =(1&"/"&MONTH(H453)&"/"&YEAR(H453))*1 -> 45809 | U453: =IF(I453="","",(1&"/"&MONTH(I453)&"/"&YEAR(I453))*1) | V453: Z
B454: MCS | D454: =INDEX(Cad_Natureza!$B$3:$C$52,MATCH('2025'!F454,Cad_Natureza!$C$3:$C$52,0),MATCH('2025'!D$2,Cad_Natureza!$B$3:$C$3,0)) -> REC3 | E454: PIX TRANSF FABRICI13/06 | F454: CPF - Ajuda de custo - Refeição | G454: MCS | H454: 45821 | J454: Ajuda de custo - Alimentação | K454: 300 | L454: =L453+K454 -> 279.29 | N454: =B454&D454&F454 -> MCSREC3CPF - Ajuda de custo - Refeição | O454: =D454&F454 -> REC3CPF - Ajuda de custo - Refeição | P454: ="MCS"&D454&F454 -> MCSREC3CPF - Ajuda de custo - Refeição | Q454: ="MCS"&D454 -> MCSREC3 | R454: =B454&D454 -> MCSREC3 | T454: =(1&"/"&MONTH(H454)&"/"&YEAR(H454))*1 -> 45809 | U454: =IF(I454="","",(1&"/"&MONTH(I454)&"/"&YEAR(I454))*1) | V454: Z
... B560: MCS | D560: =INDEX(Cad_Natureza!$B$3:$C$52,MATCH('2025'!F560,Cad_Natureza!$C$3:$C$52,0),MATCH('2025'!D$2,Cad_Natureza!$B$3:$C$3,0)) -> PENS1 | E560: PIX TRANSF Dieyla 08/07 | F560: CPF - Pensão - Aluguel | G560: MCS | H560: 45846 | J560: Pensão - aluguel 07 2025 | K560: -600 | L560: =L559+K560 -> 1392.81 | N560: =B560&D560&F560 -> MCSPENS1CPF - Pensão - Aluguel | O560: =D560&F560 -> PENS1CPF - Pensão - Aluguel | P560: ="MCS"&D560&F560 -> MCSPENS1CPF - Pensão - Aluguel | Q560: ="MCS"&D560 -> MCSPENS1 | R560: =B560&D560 -> MCSPENS1 | T560: =(1&"/"&MONTH(H560)&"/"&YEAR(H560))*1 -> 45839 | U560: =IF(I560="","",(1&"/"&MONTH(I560)&"/"&YEAR(I560))*1) | V560: X
B561: MCS | D561: =INDEX(Cad_Natureza!$B$3:$C$52,MATCH('2025'!F561,Cad_Natureza!$C$3:$C$52,0),MATCH('2025'!D$2,Cad_Natureza!$B$3:$C$3,0)) -> REC6 | E561: PIX TRANSF Maria D09/07 | F561: CPF - Pensão - Outras receitas | G561: MCS | H561: 45847 | J561: Pensão - Rcbto para comprar Antibiótico para Alice | K561: 105 | L561: 1497.81 | N561: =B561&D561&F561 -> MCSREC6CPF - Pensão - Outras receitas | O561: =D561&F561 -> REC6CPF - Pensão - Outras receitas | P561: ="MCS"&D561&F561 -> MCSREC6CPF - Pensão - Outras receitas | Q561: ="MCS"&D561 -> MCSREC6 | R561: =B561&D561 -> MCSREC6 | T561: =(1&"/"&MONTH(H561)&"/"&YEAR(H561))*1 -> 45839 | U561: =IF(I561="","",(1&"/"&MONTH(I561)&"/"&YEAR(I561))*1) | V561: X
B562: MCS | D562: =INDEX(Cad_Natureza!$B$3:$C$52,MATCH('2025'!F562,Cad_Natureza!$C$3:$C$52,0),MATCH('2025'!D$2,Cad_Natureza!$B$3:$C$3,0)) -> PENS6 | E562: RSCSS GIFARMA DROG0907 | F562: CPF - Pensão - Farmácia e Saúde | G562: MCS | H562: 45847 | J562: Pensão - Farmácia | K562: -95 | L562: 1402.81 | N562: =B562&D562&F562 -> MCSPENS6CPF - Pensão - Farmácia e Saúde | O562: =D562&F562 -> PENS6CPF - Pensão - Farmácia e Saúde | P562: ="MCS"&D562&F562 -> MCSPENS6CPF - Pensão - Farmácia e Saúde | Q562: ="MCS"&D562 -> MCSPENS6 | R562: =B562&D562 -> MCSPENS6 | T562: =(1&"/"&MONTH(H562)&"/"&YEAR(H562))*1 -> 45839 | U562: =IF(I562="","",(1&"/"&MONTH(I562)&"/"&YEAR(I562))*1) | V562: X
B563: MCS | D563: =INDEX(Cad_Natureza!$B$3:$C$52,MATCH('2025'!F563,Cad_Natureza!$C$3:$C$52,0),MATCH('2025'!D$2,Cad_Natureza!$B$3:$C$3,0)) -> OPF2 | E563: PIX QRS AUTO POSTO 10/07 | F563: CPF - Desp. Transporte / Combustível | G563: MCS | H563: 45848 | J563: Combustível | K563: -50 | L563: 1352.81 | N563: =B563&D563&F563 -> MCSOPF2CPF - Desp. Transporte / Combustível | O563: =D563&F563 -> OPF2CPF - Desp. Transporte / Combustível | P563: ="MCS"&D563&F563 -> MCSOPF2CPF - Desp. Transporte / Combustível | Q563: ="MCS"&D563 -> MCSOPF2 | R563: =B563&D563 -> MCSOPF2 | T563: =(1&"/"&MONTH(H563)&"/"&YEAR(H563))*1 -> 45839 | U563: =IF(I563="","",(1&"/"&MONTH(I563)&"/"&YEAR(I563))*1) | V563: Z
B564: MCS | D564: =INDEX(Cad_Natureza!$B$3:$C$52,MATCH('2025'!F564,Cad_Natureza!$C$3:$C$52,0),MATCH('2025'!D$2,Cad_Natureza!$B$3:$C$3,0)) -> GAST1 | E564: RSCSS VanderleiDaS1007 | F564: CPF - Desp. Lazer e Entretenimento - Bares | G564: MCS | H564: 45848 | J564: Bares | K564: -26.5 | L564: 1326.31 | N564: =B564&D564&F564 -> MCSGAST1CPF - Desp. Lazer e Entretenimento - Bares | O564: =D564&F564 -> GAST1CPF - Desp. Lazer e Entretenimento - Bares | P564: ="MCS"&D564&F564 -> MCSGAST1CPF - Desp. Lazer e Entretenimento - Bares | Q564: ="MCS"&D564 -> MCSGAST1 | R564: =B564&D564 -> MCSGAST1 | T564: =(1&"/"&MONTH(H564)&"/"&YEAR(H564))*1 -> 45839 | U564: =IF(I564="","",(1&"/"&MONTH(I564)&"/"&YEAR(I564))*1) | V564: Z
B565: MCS | D565: =INDEX(Cad_Natureza!$B$3:$C$52,MATCH('2025'!F565,Cad_Natureza!$C$3:$C$52,0),MATCH('2025'!D$2,Cad_Natureza!$B$3:$C$3,0)) -> GAST1 | E565: RSCSS VanderleiDaS1107 | F565: CPF - Desp. Lazer e Entretenimento - Bares | G565: MCS | H565: 45849 | J565: Bares | K565: -10 | L565: 1316.31 | N565: =B565&D565&F565 -> MCSGAST1CPF - Desp. Lazer e Entretenimento - Bares | O565: =D565&F565 -> GAST1CPF - Desp. Lazer e Entretenimento - Bares | P565: ="MCS"&D565&F565 -> MCSGAST1CPF - Desp. Lazer e Entretenimento - Bares | Q565: ="MCS"&D565 -> MCSGAST1 | R565: =B565&D565 -> MCSGAST1 | T565: =(1&"/"&MONTH(H565)&"/"&YEAR(H565))*1 -> 45839 | U565: =IF(I565="","",(1&"/"&MONTH(I565)&"/"&YEAR(I565))*1) | V565: Z
B566: MCS | D566: =INDEX(Cad_Natureza!$B$3:$C$52,MATCH('2025'!F566,Cad_Natureza!$C$3:$C$52,0),MATCH('2025'!D$2,Cad_Natureza!$B$3:$C$3,0)) -> GAST2 | E566: RSCSS RenatoLoiola1207 | F566: CPF - Desp. Lazer e Entretenimento - Cigarro | G566: MCS | H566: 45852 | J566: Palheiro | K566: -35 | L566: 1281.31 | N566: =B566&D566&F566 -> MCSGAST2CPF - Desp. Lazer e Entretenimento - Cigarro | O566: =D566&F566 -> GAST2CPF - Desp. Lazer e Entretenimento - Cigarro | P566: ="MCS"&D566&F566 -> MCSGAST2CPF - Desp. Lazer e Entretenimento - Cigarro | Q566: ="MCS"&D566 -> MCSGAST2 | R566: =B566&D566 -> MCSGAST2 | T566: =(1&"/"&MONTH(H566)&"/"&YEAR(H566))*1 -> 45839 | U566: =IF(I566="","",(1&"/"&MONTH(I566)&"/"&YEAR(I566))*1) | V566: Z
B567: MCS | D567: =INDEX(Cad_Natureza!$B$3:$C$52,MATCH('2025'!F567,Cad_Natureza!$C$3:$C$52,0),MATCH('2025'!D$2,Cad_Natureza!$B$3:$C$3,0)) -> GAST1 | E567: RSCSS ORIENTE BEBI1207 | F567: CPF - Desp. Lazer e Entretenimento - Bares | G567: MCS | H567: 45852 | J567: Bares - Com a Danilla | K567: -5 | L567: 1276.31 | N567: =B567&D567&F567 -> MCSGAST1CPF - Desp. Lazer e Entretenimento - Bares | O567: =D567&F567 -> GAST1CPF - Desp. Lazer e Entretenimento - Bares | P567: ="MCS"&D567&F567 -> MCSGAST1CPF - Desp. Lazer e Entretenimento - Bares | Q567: ="MCS"&D567 -> MCSGAST1 | R567: =B567&D567 -> MCSGAST1 | T567: =(1&"/"&MONTH(H567)&"/"&YEAR(H567))*1 -> 45839 | U567: =IF(I567="","",(1&"/"&MONTH(I567)&"/"&YEAR(I567))*1) | V567: Z
B568: MCS | D568: =INDEX(Cad_Natureza!$B$3:$C$52,MATCH('2025'!F568,Cad_Natureza!$C$3:$C$52,0),MATCH('2025'!D$2,Cad_Natureza!$B$3:$C$3,0)) -> GAST1 | E568: RSCSS ORIENTE BEBI1307 | F568: CPF - Desp. Lazer e Entretenimento - Bares | G568: MCS | H568: 45852 | J568: Bares - Com a Danilla | K568: -10 | L568: 1266.31 | N568: =B568&D568&F568 -> MCSGAST1CPF - Desp. Lazer e Entretenimento - Bares | O568: =D568&F568 -> GAST1CPF - Desp. Lazer e Entretenimento - Bares | P568: ="MCS"&D568&F568 -> MCSGAST1CPF - Desp. Lazer e Entretenimento - Bares | Q568: ="MCS"&D568 -> MCSGAST1 | R568: =B568&D568 -> MCSGAST1 | T568: =(1&"/"&MONTH(H568)&"/"&YEAR(H568))*1 -> 45839 | U568: =IF(I568="","",(1&"/"&MONTH(I568)&"/"&YEAR(I568))*1) | V568: Z
B569: MCS | D569: =INDEX(Cad_Natureza!$B$3:$C$52,MATCH('2025'!F569,Cad_Natureza!$C$3:$C$52,0),MATCH('2025'!D$2,Cad_Natureza!$B$3:$C$3,0)) -> GAST1 | E569: RSCSS ORIENTE BEBI1307 | F569: CPF - Desp. Lazer e Entretenimento - Bares | G569: MCS | H569: 45852 | J569: Bares - Com a Danilla | K569: -5 | L569: 1261.31 | N569: =B569&D569&F569 -> MCSGAST1CPF - Desp. Lazer e Entretenimento - Bares | O569: =D569&F569 -> GAST1CPF - Desp. Lazer e Entretenimento - Bares | P569: ="MCS"&D569&F569 -> MCSGAST1CPF - Desp. Lazer e Entretenimento - Bares | Q569: ="MCS"&D569 -> MCSGAST1 | R569: =B569&D569 -> MCSGAST1 | T569: =(1&"/"&MONTH(H569)&"/"&YEAR(H569))*1 -> 45839 | U569: =IF(I569="","",(1&"/"&MONTH(I569)&"/"&YEAR(I569))*1) | V569: Z
B570: MCS | D570: =INDEX(Cad_Natureza!$B$3:$C$52,MATCH('2025'!F570,Cad_Natureza!$C$3:$C$52,0),MATCH('2025'!D$2,Cad_Natureza!$B$3:$C$3,0)) -> GAST1 | E570: RSCSS ORIENTE BEBI1307 | F570: CPF - Desp. Lazer e Entretenimento - Bares | G570: MCS | H570: 45852 | J570: Bares - Com a Danilla | K570: -4 | L570: 1257.31 | N570: =B570&D570&F570 -> MCSGAST1CPF - Desp. Lazer e Entretenimento - Bares | O570: =D570&F570 -> GAST1CPF - Desp. Lazer e Entretenimento - Bares | P570: ="MCS"&D570&F570 -> MCSGAST1CPF - Desp. Lazer e Entretenimento - Bares | Q570: ="MCS"&D570 -> MCSGAST1 | R570: =B570&D570 -> MCSGAST1 | T570: =(1&"/"&MONTH(H570)&"/"&YEAR(H570))*1 -> 45839 | U570: =IF(I570="","",(1&"/"&MONTH(I570)&"/"&YEAR(I570))*1) | V570: Z
B571: MCS | D571: =INDEX(Cad_Natureza!$B$3:$C$52,MATCH('2025'!F571,Cad_Natureza!$C$3:$C$52,0),MATCH('2025'!D$2,Cad_Natureza!$B$3:$C$3,0)) -> GAST1 | E571: RSCSS ORIENTE BEBI1307 | F571: CPF - Desp. Lazer e Entretenimento - Bares | G571: MCS | H571: 45852 | J571: Bares - Com a Danilla | K571: -5 | L571: 1252.31 | N571: =B571&D571&F571 -> MCSGAST1CPF - Desp. Lazer e Entretenimento - Bares | O571: =D571&F571 -> GAST1CPF - Desp. Lazer e Entretenimento - Bares | P571: ="MCS"&D571&F571 -> MCSGAST1CPF - Desp. Lazer e Entretenimento - Bares | Q571: ="MCS"&D571 -> MCSGAST1 | R571: =B571&D571 -> MCSGAST1 | T571: =(1&"/"&MONTH(H571)&"/"&YEAR(H571))*1 -> 45839 | U571: =IF(I571="","",(1&"/"&MONTH(I571)&"/"&YEAR(I571))*1) | V571: Z
B572: MCS | D572: =INDEX(Cad_Natureza!$B$3:$C$52,MATCH('2025'!F572,Cad_Natureza!$C$3:$C$52,0),MATCH('2025'!D$2,Cad_Natureza!$B$3:$C$3,0)) -> GAST1 | E572: RSCSS ORIENTE BEBI1307 | F572: CPF - Desp. Lazer e Entretenimento - Bares | G572: MCS | H572: 45852 | J572: Bares - Com a Danilla | K572: -8 | L572: 1244.31 | N572: =B572&D572&F572 -> MCSGAST1CPF - Desp. Lazer e Entretenimento - Bares | O572: =D572&F572 -> GAST1CPF - Desp. Lazer e Entretenimento - Bares | P572: ="MCS"&D572&F572 -> MCSGAST1CPF - Desp. Lazer e Entretenimento - Bares | Q572: ="MCS"&D572 -> MCSGAST1 | R572: =B572&D572 -> MCSGAST1 | T572: =(1&"/"&MONTH(H572)&"/"&YEAR(H572))*1 -> 45839 | U572: =IF(I572="","",(1&"/"&MONTH(I572)&"/"&YEAR(I572))*1) | V572: Z
...

Sheet 2026
K1: =SUBTOTAL(9,K3:K687) -> -2945.87 | L1: -1
B2: EMPRESA | C2: x | D2: Natureza | E2: Descrição | F2: Centro de Resultado | G2: Entidade | H2: Data real | I2: Data prevista | J2: Observações | K2: Total | L2: Saldo banco | M2: x | N2: Empresa & CR | O2: Concat 2 | P2: Concat 3 | Q2: Concat 3 | R2: Empresa & Natureza | S2: x | T2: DATA REAL | U2: DATA PREVISTA | V2: X
B3: MCS | D3: =INDEX(Cad_Natureza!$B$3:$C$52,MATCH('2026'!F3,Cad_Natureza!$C$3:$C$52,0),MATCH('2026'!D$2,Cad_Natureza!$B$3:$C$3,0)) -> GAST2 | E3: RSCSS MP DISTIMPE0101 | F3: CPF - Desp. Lazer e Entretenimento - Cigarro | G3: MCS | H3: 46024 | J3: Palheiro | K3: -5 | L3: 347.96 | N3: =B3&D3&F3 -> MCSGAST2CPF - Desp. Lazer e Entretenimento - Cigarro | O3: =D3&F3 -> GAST2CPF - Desp. Lazer e Entretenimento - Cigarro | P3: ="MCS"&D3&F3 -> MCSGAST2CPF - Desp. Lazer e Entretenimento - Cigarro | Q3: ="MCS"&D3 -> MCSGAST2 | R3: =B3&D3 -> MCSGAST2 | T3: =(1&"/"&MONTH(H3)&"/"&YEAR(H3))*1 -> 46023 | U3: =IF(I3="","",(1&"/"&MONTH(I3)&"/"&YEAR(I3))*1) | V3: Z
B4: MCS | D4: =INDEX(Cad_Natureza!$B$3:$C$52,MATCH('2026'!F4,Cad_Natureza!$C$3:$C$52,0),MATCH('2026'!D$2,Cad_Natureza!$B$3:$C$3,0)) -> DESP2 | E4: PIX QRS Claro03/01 | F4: CPF - Desp. Telefone / Internet | G4: MCS | H4: 46027 | J4: Mensalidade do celular - em atraso | K4: -86.64 | L4: =L3+K4 -> 261.32 | N4: =B4&D4&F4 -> MCSDESP2CPF - Desp. Telefone / Internet | O4: =D4&F4 -> DESP2CPF - Desp. Telefone / Internet | P4: ="MCS"&D4&F4 -> MCSDESP2CPF - Desp. Telefone / Internet | Q4: ="MCS"&D4 -> MCSDESP2 | R4: =B4&D4 -> MCSDESP2 | T4: =(1&"/"&MONTH(H4)&"/"&YEAR(H4))*1 -> 46023 | U4: =IF(I4="","",(1&"/"&MONTH(I4)&"/"&YEAR(I4))*1) | V4: Z
B5: MCS | D5: =INDEX(Cad_Natureza!$B$3:$C$52,MATCH('2026'!F5,Cad_Natureza!$C$3:$C$52,0),MATCH('2026'!D$2,Cad_Natureza!$B$3:$C$3,0)) -> DESP2 | E5: INT /CLARO S.A 119210717 | F5: CPF - Desp. Telefone / Internet | G5: MCS | H5: 46027 | J5: Mensalidade do celular - em atraso - Parcela 1/5 | K5: -38.13 | L5: =L4+K5 -> 223.19 | N5: =B5&D5&F5 -> MCSDESP2CPF - Desp. Telefone / Internet | O5: =D5&F5 -> DESP2CPF - Desp. Telefone / Internet | P5: ="MCS"&D5&F5 -> MCSDESP2CPF - Desp. Telefone / Internet | Q5: ="MCS"&D5 -> MCSDESP2 | R5: =B5&D5 -> MCSDESP2 | T5: =(1&"/"&MONTH(H5)&"/"&YEAR(H5))*1 -> 46023 | U5: =IF(I5="","",(1&"/"&MONTH(I5)&"/"&YEAR(I5))*1) | V5: Z
B6: MCS | D6: =INDEX(Cad_Natureza!$B$3:$C$52,MATCH('2026'!F6,Cad_Natureza!$C$3:$C$52,0),MATCH('2026'!D$2,Cad_Natureza!$B$3:$C$3,0)) -> GAST2 | E6: RSCSS RosimilsonMa0301 | F6: CPF - Desp. Lazer e Entretenimento - Cigarro | G6: MCS | H6: 46027 | J6: Palheiro | K6: -10 | L6: =L5+K6 -> 213.19 | N6: =B6&D6&F6 -> MCSGAST2CPF - Desp. Lazer e Entretenimento - Cigarro | O6: =D6&F6 -> GAST2CPF - Desp. Lazer e Entretenimento - Cigarro | P6: ="MCS"&D6&F6 -> MCSGAST2CPF - Desp. Lazer e Entretenimento - Cigarro | Q6: ="MCS"&D6 -> MCSGAST2 | R6: =B6&D6 -> MCSGAST2 | T6: =(1&"/"&MONTH(H6)&"/"&YEAR(H6))*1 -> 46023 | U6: =IF(I6="","",(1&"/"&MONTH(I6)&"/"&YEAR(I6))*1) | V6: Z
B7: MCS | D7: =INDEX(Cad_Natureza!$B$3:$C$52,MATCH('2026'!F7,Cad_Natureza!$C$3:$C$52,0),MATCH('2026'!D$2,Cad_Natureza!$B$3:$C$3,0)) -> GAST2 | E7: RSCSS MARCOS PAULO0301 | F7: CPF - Desp. Lazer e Entretenimento - Cigarro | G7: MCS | H7: 46027 | J7: Palheiro | K7: -4 | L7: =L6+K7 -> 209.19 | N7: =B7&D7&F7 -> MCSGAST2CPF - Desp. Lazer e Entretenimento - Cigarro | O7: =D7&F7 -> GAST2CPF - Desp. Lazer e Entretenimento - Cigarro | P7: ="MCS"&D7&F7 -> MCSGAST2CPF - Desp. Lazer e Entretenimento - Cigarro | Q7: ="MCS"&D7 -> MCSGAST2 | R7: =B7&D7 -> MCSGAST2 | T7: =(1&"/"&MONTH(H7)&"/"&YEAR(H7))*1 -> 46023 | U7: =IF(I7="","",(1&"/"&MONTH(I7)&"/"&YEAR(I7))*1) | V7: Z
B8: MCS | D8: =INDEX(Cad_Natureza!$B$3:$C$52,MATCH('2026'!F8,Cad_Natureza!$C$3:$C$52,0),MATCH('2026'!D$2,Cad_Natureza!$B$3:$C$3,0)) -> OPF2 | E8: RSCSS POSTO SAO JO0501 | F8: CPF - Desp. Transporte / Combustível | G8: MCS | H8: 46027 | J8: Combustível | K8: -50 | L8: =L7+K8 -> 159.19 | N8: =B8&D8&F8 -> MCSOPF2CPF - Desp. Transporte / Combustível | O8: =D8&F8 -> OPF2CPF - Desp. Transporte / Combustível | P8: ="MCS"&D8&F8 -> MCSOPF2CPF - Desp. Transporte / Combustível | Q8: ="MCS"&D8 -> MCSOPF2 | R8: =B8&D8 -> MCSOPF2 | T8: =(1&"/"&MONTH(H8)&"/"&YEAR(H8))*1 -> 46023 | U8: =IF(I8="","",(1&"/"&MONTH(I8)&"/"&YEAR(I8))*1) | V8: Z
B9: MCS | D9: =INDEX(Cad_Natureza!$B$3:$C$52,MATCH('2026'!F9,Cad_Natureza!$C$3:$C$52,0),MATCH('2026'!D$2,Cad_Natureza!$B$3:$C$3,0)) -> OPF1 | E9: RSCSS TOSCANO GRIL0501 | F9: CPF - Desp. Alimentação / Refeição | G9: MCS | H9: 46027 | J9: Refeição | K9: -23.33 | L9: =L8+K9 -> 135.86 | N9: =B9&D9&F9 -> MCSOPF1CPF - Desp. Alimentação / Refeição | O9: =D9&F9 -> OPF1CPF - Desp. Alimentação / Refeição | P9: ="MCS"&D9&F9 -> MCSOPF1CPF - Desp. Alimentação / Refeição | Q9: ="MCS"&D9 -> MCSOPF1 | R9: =B9&D9 -> MCSOPF1 | T9: =(1&"/"&MONTH(H9)&"/"&YEAR(H9))*1 -> 46023 | U9: =IF(I9="","",(1&"/"&MONTH(I9)&"/"&YEAR(I9))*1) | V9: X
B10: MCS | D10: =INDEX(Cad_Natureza!$B$3:$C$52,MATCH('2026'!F10,Cad_Natureza!$C$3:$C$52,0),MATCH('2026'!D$2,Cad_Natureza!$B$3:$C$3,0)) -> GAST1 | E10: RSCSS MP 243303760501 | F10: CPF - Desp. Lazer e Entretenimento - Bares | G10: MCS | H10: 46027 | J10: Bares | K10: -16 | L10: =L9+K10 -> 119.86 | N10: =B10&D10&F10 -> MCSGAST1CPF - Desp. Lazer e Entretenimento - Bares | O10: =D10&F10 -> GAST1CPF - Desp. Lazer e Entretenimento - Bares | P10: ="MCS"&D10&F10 -> MCSGAST1CPF - Desp. Lazer e Entretenimento - Bares | Q10: ="MCS"&D10 -> MCSGAST1 | R10: =B10&D10 -> MCSGAST1 | T10: =(1&"/"&MONTH(H10)&"/"&YEAR(H10))*1 -> 46023 | U10: =IF(I10="","",(1&"/"&MONTH(I10)&"/"&YEAR(I10))*1) | V10: X
B11: MCS | D11: =INDEX(Cad_Natureza!$B$3:$C$52,MATCH('2026'!F11,Cad_Natureza!$C$3:$C$52,0),MATCH('2026'!D$2,Cad_Natureza!$B$3:$C$3,0)) -> PENS6 | E11: RSCSS DROGARIA MEN0501 | F11: CPF - Pensão - Farmácia e Saúde | G11: MCS | H11: 46027 | J11: Pensão - Farmácia | K11: -14.49 | L11: =L10+K11 -> 105.37 | N11: =B11&D11&F11 -> MCSPENS6CPF - Pensão - Farmácia e Saúde | O11: =D11&F11 -> PENS6CPF - Pensão - Farmácia e Saúde | P11: ="MCS"&D11&F11 -> MCSPENS6CPF - Pensão - Farmácia e Saúde | Q11: ="MCS"&D11 -> MCSPENS6 | R11: =B11&D11 -> MCSPENS6 | T11: =(1&"/"&MONTH(H11)&"/"&YEAR(H11))*1 -> 46023 | U11: =IF(I11="","",(1&"/"&MONTH(I11)&"/"&YEAR(I11))*1) | V11: Z
B12: MCS | D12: =INDEX(Cad_Natureza!$B$3:$C$52,MATCH('2026'!F12,Cad_Natureza!$C$3:$C$52,0),MATCH('2026'!D$2,Cad_Natureza!$B$3:$C$3,0)) -> GAST1 | E12: RSCSS LindomarBarb0501 | F12: CPF - Desp. Lazer e Entretenimento - Bares | G12: MCS | H12: 46027 | J12: Bares | K12: -10 | L12: =L11+K12 -> 95.37 | N12: =B12&D12&F12 -> MCSGAST1CPF - Desp. Lazer e Entretenimento - Bares | O12: =D12&F12 -> GAST1CPF - Desp. Lazer e Entretenimento - Bares | P12: ="MCS"&D12&F12 -> MCSGAST1CPF - Desp. Lazer e Entretenimento - Bares | Q12: ="MCS"&D12 -> MCSGAST1 | R12: =B12&D12 -> MCSGAST1 | T12: =(1&"/"&MONTH(H12)&"/"&YEAR(H12))*1 -> 46023 | U12: =IF(I12="","",(1&"/"&MONTH(I12)&"/"&YEAR(I12))*1) | V12: Z
B13: MCS | D13: =INDEX(Cad_Natureza!$B$3:$C$52,MATCH('2026'!F13,Cad_Natureza!$C$3:$C$52,0),MATCH('2026'!D$2,Cad_Natureza!$B$3:$C$3,0)) -> FIN2 | E13: TAR PACOTE ITAU DEZ/25 | F13: CPF - Desp. Financeiras - Juros / Tarifas | G13: MCS | H13: 46027 | J13: Tarifas bancárias | K13: -28 | L13: =L12+K13 -> 67.37 | N13: =B13&D13&F13 -> MCSFIN2CPF - Desp. Financeiras - Juros / Tarifas | O13: =D13&F13 -> FIN2CPF - Desp. Financeiras - Juros / Tarifas | P13: ="MCS"&D13&F13 -> MCSFIN2CPF - Desp. Financeiras - Juros / Tarifas | Q13: ="MCS"&D13 -> MCSFIN2 | R13: =B13&D13 -> MCSFIN2 | T13: =(1&"/"&MONTH(H13)&"/"&YEAR(H13))*1 -> 46023 | U13: =IF(I13="","",(1&"/"&MONTH(I13)&"/"&YEAR(I13))*1) | V13: Z
B14: MCS | D14: =INDEX(Cad_Natureza!$B$3:$C$52,MATCH('2026'!F14,Cad_Natureza!$C$3:$C$52,0),MATCH('2026'!D$2,Cad_Natureza!$B$3:$C$3,0)) -> OPF2 | E14: RSCSS POSTO SAO JO0601 | F14: CPF - Desp. Transporte / Combustível | G14: MCS | H14: 46028 | J14: Combustível | K14: -40 | L14: =L13+K14 -> 27.37 | N14: =B14&D14&F14 -> MCSOPF2CPF - Desp. Transporte / Combustível | O14: =D14&F14 -> OPF2CPF - Desp. Transporte / Combustível | P14: ="MCS"&D14&F14 -> MCSOPF2CPF - Desp. Transporte / Combustível | Q14: ="MCS"&D14 -> MCSOPF2 | R14: =B14&D14 -> MCSOPF2 | T14: =(1&"/"&MONTH(H14)&"/"&YEAR(H14))*1 -> 46023 | U14: =IF(I14="","",(1&"/"&MONTH(I14)&"/"&YEAR(I14))*1) | V14: Z
B15: MCS | D15: =INDEX(Cad_Natureza!$B$3:$C$52,MATCH('2026'!F15,Cad_Natureza!$C$3:$C$52,0),MATCH('2026'!D$2,Cad_Natureza!$B$3:$C$3,0)) -> GAST1 | E15: RSCSS MP 243303760601 | F15: CPF - Desp. Lazer e Entretenimento - Bares | G15: MCS | H15: 46028 | J15: Bares - Derley | K15: -10 | L15: =L14+K15 -> 17.37 | N15: =B15&D15&F15 -> MCSGAST1CPF - Desp. Lazer e Entretenimento - Bares | O15: =D15&F15 -> GAST1CPF - Desp. Lazer e Entretenimento - Bares | P15: ="MCS"&D15&F15 -> MCSGAST1CPF - Desp. Lazer e Entretenimento - Bares | Q15: ="MCS"&D15 -> MCSGAST1 | R15: =B15&D15 -> MCSGAST1 | T15: =(1&"/"&MONTH(H15)&"/"&YEAR(H15))*1 -> 46023 | U15: =IF(I15="","",(1&"/"&MONTH(I15)&"/"&YEAR(I15))*1) | V15: Z
... B650: MCS | D650: =INDEX(Cad_Natureza!$B$3:$C$52,MATCH('2026'!F650,Cad_Natureza!$C$3:$C$52,0),MATCH('2026'!D$2,Cad_Natureza!$B$3:$C$3,0)) -> PENS2 | E650: PIX QRS EQUATORIAL 15/06 | F650: CPF - Pensão - Energia | G650: MCS | H650: 46188 | J650: Pensão - Conta de energia ref. 04/2026 | K650: -490.89 | L650: =L649+K650 -> 596.13 | N650: =B650&D650&F650 -> MCSPENS2CPF - Pensão - Energia | O650: =D650&F650 -> PENS2CPF - Pensão - Energia | P650: ="MCS"&D650&F650 -> MCSPENS2CPF - Pensão - Energia | Q650: ="MCS"&D650 -> MCSPENS2 | R650: =B650&D650 -> MCSPENS2 | T650: =(1&"/"&MONTH(H650)&"/"&YEAR(H650))*1 -> 46174 | U650: =IF(I650="","",(1&"/"&MONTH(I650)&"/"&YEAR(I650))*1) | V650: X
B651: MCS | D651: =INDEX(Cad_Natureza!$B$3:$C$52,MATCH('2026'!F651,Cad_Natureza!$C$3:$C$52,0),MATCH('2026'!D$2,Cad_Natureza!$B$3:$C$3,0)) -> #N/A | G651: MCS | N651: =B651&D651&F651 -> #N/A | O651: =D651&F651 -> #N/A | P651: ="MCS"&D651&F651 -> #N/A | Q651: ="MCS"&D651 -> #N/A | R651: =B651&D651 -> #N/A | T651: =(1&"/"&MONTH(H651)&"/"&YEAR(H651))*1 -> 1 | U651: =IF(I651="","",(1&"/"&MONTH(I651)&"/"&YEAR(I651))*1) | V651: X
B652: MCS | D652: =INDEX(Cad_Natureza!$B$3:$C$52,MATCH('2026'!F652,Cad_Natureza!$C$3:$C$52,0),MATCH('2026'!D$2,Cad_Natureza!$B$3:$C$3,0)) -> #N/A | G652: MCS | N652: =B652&D652&F652 -> #N/A | O652: =D652&F652 -> #N/A | P652: ="MCS"&D652&F652 -> #N/A | Q652: ="MCS"&D652 -> #N/A | R652: =B652&D652 -> #N/A | T652: =(1&"/"&MONTH(H652)&"/"&YEAR(H652))*1 -> 1 | U652: =IF(I652="","",(1&"/"&MONTH(I652)&"/"&YEAR(I652))*1) | V652: Z
B653: MCS | D653: =INDEX(Cad_Natureza!$B$3:$C$52,MATCH('2026'!F653,Cad_Natureza!$C$3:$C$52,0),MATCH('2026'!D$2,Cad_Natureza!$B$3:$C$3,0)) -> #N/A | G653: MCS | N653: =B653&D653&F653 -> #N/A | O653: =D653&F653 -> #N/A | P653: ="MCS"&D653&F653 -> #N/A | Q653: ="MCS"&D653 -> #N/A | R653: =B653&D653 -> #N/A | T653: =(1&"/"&MONTH(H653)&"/"&YEAR(H653))*1 -> 1 | U653: =IF(I653="","",(1&"/"&MONTH(I653)&"/"&YEAR(I653))*1) | V653: Z
B654: MCS | D654: =INDEX(Cad_Natureza!$B$3:$C$52,MATCH('2026'!F654,Cad_Natureza!$C$3:$C$52,0),MATCH('2026'!D$2,Cad_Natureza!$B$3:$C$3,0)) -> #N/A | G654: MCS | N654: =B654&D654&F654 -> #N/A | O654: =D654&F654 -> #N/A | P654: ="MCS"&D654&F654 -> #N/A | Q654: ="MCS"&D654 -> #N/A | R654: =B654&D654 -> #N/A | T654: =(1&"/"&MONTH(H654)&"/"&YEAR(H654))*1 -> 1 | U654: =IF(I654="","",(1&"/"&MONTH(I654)&"/"&YEAR(I654))*1) | V654: Z
B655: MCS | D655: =INDEX(Cad_Natureza!$B$3:$C$52,MATCH('2026'!F655,Cad_Natureza!$C$3:$C$52,0),MATCH('2026'!D$2,Cad_Natureza!$B$3:$C$3,0)) -> #N/A | G655: MCS | N655: =B655&D655&F655 -> #N/A | O655: =D655&F655 -> #N/A | P655: ="MCS"&D655&F655 -> #N/A | Q655: ="MCS"&D655 -> #N/A | R655: =B655&D655 -> #N/A | T655: =(1&"/"&MONTH(H655)&"/"&YEAR(H655))*1 -> 1 | U655: =IF(I655="","",(1&"/"&MONTH(I655)&"/"&YEAR(I655))*1) | V655: Z
B656: MCS | D656: =INDEX(Cad_Natureza!$B$3:$C$52,MATCH('2026'!F656,Cad_Natureza!$C$3:$C$52,0),MATCH('2026'!D$2,Cad_Natureza!$B$3:$C$3,0)) -> #N/A | G656: MCS | N656: =B656&D656&F656 -> #N/A | O656: =D656&F656 -> #N/A | P656: ="MCS"&D656&F656 -> #N/A | Q656: ="MCS"&D656 -> #N/A | R656: =B656&D656 -> #N/A | T656: =(1&"/"&MONTH(H656)&"/"&YEAR(H656))*1 -> 1 | U656: =IF(I656="","",(1&"/"&MONTH(I656)&"/"&YEAR(I656))*1) | V656: Z
B657: MCS | D657: =INDEX(Cad_Natureza!$B$3:$C$52,MATCH('2026'!F657,Cad_Natureza!$C$3:$C$52,0),MATCH('2026'!D$2,Cad_Natureza!$B$3:$C$3,0)) -> #N/A | G657: MCS | J657: DAS - MCS Serviços ref. 09/2025 - Parcelar | K657: =-5000*6% -> -300 | N657: =B657&D657&F657 -> #N/A | O657: =D657&F657 -> #N/A | P657: ="MCS"&D657&F657 -> #N/A | Q657: ="MCS"&D657 -> #N/A | R657: =B657&D657 -> #N/A | T657: =(1&"/"&MONTH(H657)&"/"&YEAR(H657))*1 -> 1 | U657: =IF(I657="","",(1&"/"&MONTH(I657)&"/"&YEAR(I657))*1) | V657: X
B658: MCS | D658: =INDEX(Cad_Natureza!$B$3:$C$52,MATCH('2026'!F658,Cad_Natureza!$C$3:$C$52,0),MATCH('2026'!D$2,Cad_Natureza!$B$3:$C$3,0)) -> #N/A | G658: MCS | J658: DAS - MCS Serviços ref. 10/2025 - Parcelar | K658: =-5000*6% -> -300 | N658: =B658&D658&F658 -> #N/A | O658: =D658&F658 -> #N/A | P658: ="MCS"&D658&F658 -> #N/A | Q658: ="MCS"&D658 -> #N/A | R658: =B658&D658 -> #N/A | T658: =(1&"/"&MONTH(H658)&"/"&YEAR(H658))*1 -> 1 | U658: =IF(I658="","",(1&"/"&MONTH(I658)&"/"&YEAR(I658))*1) | V658: X
B659: MCS | D659: =INDEX(Cad_Natureza!$B$3:$C$52,MATCH('2026'!F659,Cad_Natureza!$C$3:$C$52,0),MATCH('2026'!D$2,Cad_Natureza!$B$3:$C$3,0)) -> #N/A | G659: MCS | J659: DAS - MCS Serviços ref. 11/2025 - Parcelar | K659: =-5000*6% -> -300 | N659: =B659&D659&F659 -> #N/A | O659: =D659&F659 -> #N/A | P659: ="MCS"&D659&F659 -> #N/A | Q659: ="MCS"&D659 -> #N/A | R659: =B659&D659 -> #N/A | T659: =(1&"/"&MONTH(H659)&"/"&YEAR(H659))*1 -> 1 | U659: =IF(I659="","",(1&"/"&MONTH(I659)&"/"&YEAR(I659))*1) | V659: Z
B660: MCS | D660: =INDEX(Cad_Natureza!$B$3:$C$52,MATCH('2026'!F660,Cad_Natureza!$C$3:$C$52,0),MATCH('2026'!D$2,Cad_Natureza!$B$3:$C$3,0)) -> #N/A | G660: MCS | J660: DAS - MCS Serviços ref. 12/2025 - Parcelar | K660: =-5000*6% -> -300 | N660: =B660&D660&F660 -> #N/A | O660: =D660&F660 -> #N/A | P660: ="MCS"&D660&F660 -> #N/A | Q660: ="MCS"&D660 -> #N/A | R660: =B660&D660 -> #N/A | T660: =(1&"/"&MONTH(H660)&"/"&YEAR(H660))*1 -> 1 | U660: =IF(I660="","",(1&"/"&MONTH(I660)&"/"&YEAR(I660))*1) | V660: Z
B661: MCS | D661: =INDEX(Cad_Natureza!$B$3:$C$52,MATCH('2026'!F661,Cad_Natureza!$C$3:$C$52,0),MATCH('2026'!D$2,Cad_Natureza!$B$3:$C$3,0)) -> #N/A | G661: MCS | J661: DAS - MCS Serviços ref. 01/2026 - Parcelar | K661: =-5000*6% -> -300 | N661: =B661&D661&F661 -> #N/A | O661: =D661&F661 -> #N/A | P661: ="MCS"&D661&F661 -> #N/A | Q661: ="MCS"&D661 -> #N/A | R661: =B661&D661 -> #N/A | T661: =(1&"/"&MONTH(H661)&"/"&YEAR(H661))*1 -> 1 | U661: =IF(I661="","",(1&"/"&MONTH(I661)&"/"&YEAR(I661))*1) | V661: Z
B662: MCS | D662: =INDEX(Cad_Natureza!$B$3:$C$52,MATCH('2026'!F662,Cad_Natureza!$C$3:$C$52,0),MATCH('2026'!D$2,Cad_Natureza!$B$3:$C$3,0)) -> #N/A | G662: MCS | J662: DAS - MCS Serviços ref. 02/2026 - Parcelar | K662: =-1500*6% -> -90 | N662: =B662&D662&F662 -> #N/A | O662: =D662&F662 -> #N/A | P662: ="MCS"&D662&F662 -> #N/A | Q662: ="MCS"&D662 -> #N/A | R662: =B662&D662 -> #N/A | T662: =(1&"/"&MONTH(H662)&"/"&YEAR(H662))*1 -> 1 | U662: =IF(I662="","",(1&"/"&MONTH(I662)&"/"&YEAR(I662))*1) | V662: Z
B663: MCS | G663: MCS | J663: DAS - MCS Serviços ref. 03/2026 - Parcelar | K663: =-5000*6% -> -300 | N663: =B663&D663&F663 -> MCS | O663: =D663&F663 | P663: ="MCS"&D663&F663 -> MCS | Q663: ="MCS"&D663 -> MCS | R663: =B663&D663 -> MCS | T663: =(1&"/"&MONTH(H663)&"/"&YEAR(H663))*1 -> 1 | U663: =IF(I663="","",(1&"/"&MONTH(I663)&"/"&YEAR(I663))*1)
B664: MCS | G664: MCS | J664: DAS - MCS Serviços ref. 04/2026 - Parcelar | K664: =-5000*6% -> -300 | N664: =B664&D664&F664 -> MCS | O664: =D664&F664 | P664: ="MCS"&D664&F664 -> MCS | Q664: ="MCS"&D664 -> MCS | R664: =B664&D664 -> MCS | T664: =(1&"/"&MONTH(H664)&"/"&YEAR(H664))*1 -> 1 | U664: =IF(I664="","",(1&"/"&MONTH(I664)&"/"&YEAR(I664))*1)
B665: MCS | G665: MCS | J665: DAS - MCS Serviços ref. 05/2026 - Parcelar | K665: =-5000*6% -> -300 | N665: =B665&D665&F665 -> MCS | O665: =D665&F665 | P665: ="MCS"&D665&F665 -> MCS | Q665: ="MCS"&D665 -> MCS | R665: =B665&D665 -> MCS | T665: =(1&"/"&MONTH(H665)&"/"&YEAR(H665))*1 -> 1 | U665: =IF(I665="","",(1&"/"&MONTH(I665)&"/"&YEAR(I665))*1)
B666: MCS | D666: =INDEX(Cad_Natureza!$B$3:$C$52,MATCH('2026'!F666,Cad_Natureza!$C$3:$C$52,0),MATCH('2026'!D$2,Cad_Natureza!$B$3:$C$3,0)) -> REC4 | E666: PIX TRANSF MCS SER10/11 | F666: CPF - Transf. Da conta PJ para a conta PF | G666: MCS | J666: Receita com prestação de serviços | K666: 5000 | L666: =L401+K666 -> 5477.15 | N666: =B666&D666&F666 -> MCSREC4CPF - Transf. Da conta PJ para a conta PF | O666: =D666&F666 -> REC4CPF - Transf. Da conta PJ para a conta PF | P666: ="MCS"&D666&F666 -> MCSREC4CPF - Transf. Da conta PJ para a conta PF | Q666: ="MCS"&D666 -> MCSREC4 | R666: =B666&D666 -> MCSREC4 | T666: =(1&"/"&MONTH(H666)&"/"&YEAR(H666))*1 -> 1 | U666: =IF(I666="","",(1&"/"&MONTH(I666)&"/"&YEAR(I666))*1)
B667: MCS | D667: =INDEX(Cad_Natureza!$B$3:$C$52,MATCH('2026'!F667,Cad_Natureza!$C$3:$C$52,0),MATCH('2026'!D$2,Cad_Natureza!$B$3:$C$3,0)) -> DESP1 | E667: Refeições para o mês | F667: CPF - Desp. Cartão de crédito | G667: MCS | K667: =Prev_Combust_Refei!K33 -> -440 | L667: =L666+K667 -> 5037.15 | N667: =B667&D667&F667 -> MCSDESP1CPF - Desp. Cartão de crédito | O667: =D667&F667 -> DESP1CPF - Desp. Cartão de crédito | P667: ="MCS"&D667&F667 -> MCSDESP1CPF - Desp. Cartão de crédito | Q667: ="MCS"&D667 -> MCSDESP1 | R667: =B667&D667 -> MCSDESP1 | T667: =(1&"/"&MONTH(H667)&"/"&YEAR(H667))*1 -> 1 | U667: =IF(I667="","",(1&"/"&MONTH(I667)&"/"&YEAR(I667))*1)
B668: MCS | D668: =INDEX(Cad_Natureza!$B$3:$C$52,MATCH('2026'!F668,Cad_Natureza!$C$3:$C$52,0),MATCH('2026'!D$2,Cad_Natureza!$B$3:$C$3,0)) -> FIN1 | E668: Combustível para o mês | F668: CPF - Desp. Financeiras - Empréstimos | G668: MCS | K668: =Prev_Combust_Refei!I33 -> -352 | L668: =L667+K668 -> 4685.15 | N668: =B668&D668&F668 -> MCSFIN1CPF - Desp. Financeiras - Empréstimos | O668: =D668&F668 -> FIN1CPF - Desp. Financeiras - Empréstimos | P668: ="MCS"&D668&F668 -> MCSFIN1CPF - Desp. Financeiras - Empréstimos | Q668: ="MCS"&D668 -> MCSFIN1 | R668: =B668&D668 -> MCSFIN1 | T668: =(1&"/"&MONTH(H668)&"/"&YEAR(H668))*1 -> 1 | U668: =IF(I668="","",(1&"/"&MONTH(I668)&"/"&YEAR(I668))*1)
B669: MCS | D669: =INDEX(Cad_Natureza!$B$3:$C$52,MATCH('2026'!F669,Cad_Natureza!$C$3:$C$52,0),MATCH('2026'!D$2,Cad_Natureza!$B$3:$C$3,0)) -> PENS2 | E669: Pensão - Conta de energia ref. 07/2025, vcto 02/08 | F669: CPF - Pensão - Energia | G669: MCS | J669: Pensão - Conta de energia ref. 04/2026 | K669: -816.87 | L669: =L668+K669 -> 3868.28 | N669: =B669&D669&F669 -> MCSPENS2CPF - Pensão - Energia | O669: =D669&F669 -> PENS2CPF - Pensão - Energia | P669: ="MCS"&D669&F669 -> MCSPENS2CPF - Pensão - Energia | Q669: ="MCS"&D669 -> MCSPENS2 | R669: =B669&D669 -> MCSPENS2 | T669: =(1&"/"&MONTH(H669)&"/"&YEAR(H669))*1 -> 1 | U669: =IF(I669="","",(1&"/"&MONTH(I669)&"/"&YEAR(I669))*1) | V669: X
B670: MCS | D670: =INDEX(Cad_Natureza!$B$3:$C$52,MATCH('2026'!F670,Cad_Natureza!$C$3:$C$52,0),MATCH('2026'!D$2,Cad_Natureza!$B$3:$C$3,0)) -> PENS5 | E670: Pensão - Conta de água atrasada ref. 07/2025 | F670: CPF - Pensão - Água | G670: MCS | J670: Pensão - Conta de água ref. 04/2025 | K670: =-135.47 -> -135.47 | L670: =L669+K670 -> 3732.81 | N670: =B670&D670&F670 -> MCSPENS5CPF - Pensão - Água | O670: =D670&F670 -> PENS5CPF - Pensão - Água | P670: ="MCS"&D670&F670 -> MCSPENS5CPF - Pensão - Água | Q670: ="MCS"&D670 -> MCSPENS5 | R670: =B670&D670 -> MCSPENS5 | T670: =(1&"/"&MONTH(H670)&"/"&YEAR(H670))*1 -> 1 | U670: =IF(I670="","",(1&"/"&MONTH(I670)&"/"&YEAR(I670))*1) | V670: X
A671: x | B671: MCS | D671: =INDEX(Cad_Natureza!$B$3:$C$52,MATCH('2026'!F671,Cad_Natureza!$C$3:$C$52,0),MATCH('2026'!D$2,Cad_Natureza!$B$3:$C$3,0)) -> PENS1 | E671: Pensão - Aluguel 09/2025 | F671: CPF - Pensão - Aluguel | G671: MCS | J671: Pensão - Aluguel 05/2025 | K671: -700 | L671: =L670+K671 -> 3032.81 | N671: =B671&D671&F671 -> MCSPENS1CPF - Pensão - Aluguel | O671: =D671&F671 -> PENS1CPF - Pensão - Aluguel | P671: ="MCS"&D671&F671 -> MCSPENS1CPF - Pensão - Aluguel | Q671: ="MCS"&D671 -> MCSPENS1 | R671: =B671&D671 -> MCSPENS1 | T671: =(1&"/"&MONTH(H671)&"/"&YEAR(H671))*1 -> 1 | U671: =IF(I671="","",(1&"/"&MONTH(I671)&"/"&YEAR(I671))*1) | V671: X
B672: MCS | D672: =INDEX(Cad_Natureza!$B$3:$C$52,MATCH('2026'!F672,Cad_Natureza!$C$3:$C$52,0),MATCH('2026'!D$2,Cad_Natureza!$B$3:$C$3,0)) -> PENS3 | E672: Pensão - Plano de saúde de Alice e Davi ref. 08/2025 | F672: CPF - Pensão - Plano de saúde | G672: MCS | J672: Pensão - Plano de saúde de Alice e Davi ref. 04/2025 | K672: -495.5 | L672: =L671+K672 -> 2537.31 | N672: =B672&D672&F672 -> MCSPENS3CPF - Pensão - Plano de saúde | O672: =D672&F672 -> PENS3CPF - Pensão - Plano de saúde | P672: ="MCS"&D672&F672 -> MCSPENS3CPF - Pensão - Plano de saúde | Q672: ="MCS"&D672 -> MCSPENS3 | R672: =B672&D672 -> MCSPENS3 | T672: =(1&"/"&MONTH(H672)&"/"&YEAR(H672))*1 -> 1 | U672: =IF(I672="","",(1&"/"&MONTH(I672)&"/"&YEAR(I672))*1) | V672: X
B673: MCS | D673: =INDEX(Cad_Natureza!$B$3:$C$52,MATCH('2026'!F673,Cad_Natureza!$C$3:$C$52,0),MATCH('2026'!D$2,Cad_Natureza!$B$3:$C$3,0)) -> PENS8 | E673: CPF - Pensão - Alimentação | F673: CPF - Pensão - Alimentação | G673: MCS | K673: 0 | L673: =L672+K673 -> 2537.31 | N673: =B673&D673&F673 -> MCSPENS8CPF - Pensão - Alimentação | O673: =D673&F673 -> PENS8CPF - Pensão - Alimentação | P673: ="MCS"&D673&F673 -> MCSPENS8CPF - Pensão - Alimentação | Q673: ="MCS"&D673 -> MCSPENS8 | R673: =B673&D673 -> MCSPENS8 | T673: =(1&"/"&MONTH(H673)&"/"&YEAR(H673))*1 -> 1 | U673: =IF(I673="","",(1&"/"&MONTH(I673)&"/"&YEAR(I673))*1)
B674: MCS | D674: =INDEX(Cad_Natureza!$B$3:$C$52,MATCH('2026'!F674,Cad_Natureza!$C$3:$C$52,0),MATCH('2026'!D$2,Cad_Natureza!$B$3:$C$3,0)) -> PENS9 | E674: CPF - Pensão - Outros Gastos | F674: CPF - Pensão - Outros Gastos | G674: MCS | K674: 0 | L674: =L673+K674 -> 2537.31 | N674: =B674&D674&F674 -> MCSPENS9CPF - Pensão - Outros Gastos | O674: =D674&F674 -> PENS9CPF - Pensão - Outros Gastos | P674: ="MCS"&D674&F674 -> MCSPENS9CPF - Pensão - Outros Gastos | Q674: ="MCS"&D674 -> MCSPENS9 | R674: =B674&D674 -> MCSPENS9 | T674: =(1&"/"&MONTH(H674)&"/"&YEAR(H674))*1 -> 1 | U674: =IF(I674="","",(1&"/"&MONTH(I674)&"/"&YEAR(I674))*1)
...

Sheet CAIXA_REAL
A2: MCS | B2: FLUXO DE CAIXA ANO - MCS
A3: MCS | D3: SELECIONE A ENTIDADE QUE PAGOU OU RECEBEU => | E3: MCS | T3: RESUMO FLUXO CAIXA
A4: MCS | D4: SELECIONE O CENTRO DE RESULTADO => | E4: TODOS CRs | T4: GRUPO | U4: TOTAL | V4: A.V. %
A5: Sinko | T5: REC | U5: =SUMIFS($E$7:$E$40,$B$7:$B$40,T5) -> 33591.75 | V5: =IFERROR(ABS(U5/$U$5),0) -> 1
A6: TODAS | B6: Grupo | C6: Natureza | D6: ENTRADAS | E6: ACUM | F6: 46023 | G6: 46054 | H6: 46082 | I6: 46113 | J6: 46143 | K6: 46174 | L6: 46204 | M6: 46235 | N6: 46266 | O6: 46296 | P6: 46327 | Q6: 46357 | T6: PENS | U6: =SUMIFS($E$7:$E$40,$B$7:$B$40,T6) -> -11734.05 | V6: =IFERROR(ABS(U6/$U$5),0) -> 0.34931345
B7: REC | C7: REC1 | D7: CPF - Remun. Salário / Pró-Labore | E7: =SUM(F7:Q7) -> 0 | F7: =IF((AND($E$3="MCS",$E$4="TODOS CRs")), SUMIFS('2026'!$K:$K,'2026'!$R:$R,$E$3&$C7,'2026'!$T:$T,F$6), SUMIFS('2026'!$K:$K,'2026'!$N:$N,$E$3&$C7&$E$4,'2026'!$T:$T,F$6)) -> 0 | G7: =IF((AND($E$3="MCS",$E$4="TODOS CRs")), SUMIFS('2026'!$K:$K,'2026'!$R:$R,$E$3&$C7,'2026'!$T:$T,G$6), SUMIFS('2026'!$K:$K,'2026'!$N:$N,$E$3&$C7&$E$4,'2026'!$T:$T,G$6)) -> 0 | H7: =IF((AND($E$3="MCS",$E$4="TODOS CRs")), SUMIFS('2026'!$K:$K,'2026'!$R:$R,$E$3&$C7,'2026'!$T:$T,H$6), SUMIFS('2026'!$K:$K,'2026'!$N:$N,$E$3&$C7&$E$4,'2026'!$T:$T,H$6)) -> 0 | I7: =IF((AND($E$3="MCS",$E$4="TODOS CRs")), SUMIFS('2026'!$K:$K,'2026'!$R:$R,$E$3&$C7,'2026'!$T:$T,I$6), SUMIFS('2026'!$K:$K,'2026'!$N:$N,$E$3&$C7&$E$4,'2026'!$T:$T,I$6)) -> 0 | J7: =IF((AND($E$3="MCS",$E$4="TODOS CRs")), SUMIFS('2026'!$K:$K,'2026'!$R:$R,$E$3&$C7,'2026'!$T:$T,J$6), SUMIFS('2026'!$K:$K,'2026'!$N:$N,$E$3&$C7&$E$4,'2026'!$T:$T,J$6)) -> 0 | K7: =IF((AND($E$3="MCS",$E$4="TODOS CRs")), SUMIFS('2026'!$K:$K,'2026'!$R:$R,$E$3&$C7,'2026'!$T:$T,K$6), SUMIFS('2026'!$K:$K,'2026'!$N:$N,$E$3&$C7&$E$4,'2026'!$T:$T,K$6)) -> 0 | L7: =IF((AND($E$3="MCS",$E$4="TODOS CRs")), SUMIFS('2026'!$K:$K,'2026'!$R:$R,$E$3&$C7,'2026'!$T:$T,L$6), SUMIFS('2026'!$K:$K,'2026'!$N:$N,$E$3&$C7&$E$4,'2026'!$T:$T,L$6)) -> 0 | M7: =IF((AND($E$3="MCS",$E$4="TODOS CRs")), SUMIFS('2026'!$K:$K,'2026'!$R:$R,$E$3&$C7,'2026'!$T:$T,M$6), SUMIFS('2026'!$K:$K,'2026'!$N:$N,$E$3&$C7&$E$4,'2026'!$T:$T,M$6)) -> 0 | ... Q7: =IF((AND($E$3="MCS",$E$4="TODOS CRs")), SUMIFS('2026'!$K:$K,'2026'!$R:$R,$E$3&$C7,'2026'!$T:$T,Q$6), SUMIFS('2026'!$K:$K,'2026'!$N:$N,$E$3&$C7&$E$4,'2026'!$T:$T,Q$6)) -> 0 | T7: OPF | U7: =SUMIFS($E$7:$E$40,$B$7:$B$40,T7) -> -6840.46 | V7: =IFERROR(ABS(U7/$U$5),0) -> 0.20363512
B8: REC | C8: REC2 | D8: CPF - Ajuda de custo - Combustível | E8: =SUM(F8:Q8) -> 0 | F8: =IF((AND($E$3="MCS",$E$4="TODOS CRs")), SUMIFS('2026'!$K:$K,'2026'!$R:$R,$E$3&$C8,'2026'!$T:$T,F$6), SUMIFS('2026'!$K:$K,'2026'!$N:$N,$E$3&$C8&$E$4,'2026'!$T:$T,F$6)) -> 0 | G8: =IF((AND($E$3="MCS",$E$4="TODOS CRs")), SUMIFS('2026'!$K:$K,'2026'!$R:$R,$E$3&$C8,'2026'!$T:$T,G$6), SUMIFS('2026'!$K:$K,'2026'!$N:$N,$E$3&$C8&$E$4,'2026'!$T:$T,G$6)) -> 0 | H8: =IF((AND($E$3="MCS",$E$4="TODOS CRs")), SUMIFS('2026'!$K:$K,'2026'!$R:$R,$E$3&$C8,'2026'!$T:$T,H$6), SUMIFS('2026'!$K:$K,'2026'!$N:$N,$E$3&$C8&$E$4,'2026'!$T:$T,H$6)) -> 0 | I8: =IF((AND($E$3="MCS",$E$4="TODOS CRs")), SUMIFS('2026'!$K:$K,'2026'!$R:$R,$E$3&$C8,'2026'!$T:$T,I$6), SUMIFS('2026'!$K:$K,'2026'!$N:$N,$E$3&$C8&$E$4,'2026'!$T:$T,I$6)) -> 0 | J8: =IF((AND($E$3="MCS",$E$4="TODOS CRs")), SUMIFS('2026'!$K:$K,'2026'!$R:$R,$E$3&$C8,'2026'!$T:$T,J$6), SUMIFS('2026'!$K:$K,'2026'!$N:$N,$E$3&$C8&$E$4,'2026'!$T:$T,J$6)) -> 0 | K8: =IF((AND($E$3="MCS",$E$4="TODOS CRs")), SUMIFS('2026'!$K:$K,'2026'!$R:$R,$E$3&$C8,'2026'!$T:$T,K$6), SUMIFS('2026'!$K:$K,'2026'!$N:$N,$E$3&$C8&$E$4,'2026'!$T:$T,K$6)) -> 0 | L8: =IF((AND($E$3="MCS",$E$4="TODOS CRs")), SUMIFS('2026'!$K:$K,'2026'!$R:$R,$E$3&$C8,'2026'!$T:$T,L$6), SUMIFS('2026'!$K:$K,'2026'!$N:$N,$E$3&$C8&$E$4,'2026'!$T:$T,L$6)) -> 0 | M8: =IF((AND($E$3="MCS",$E$4="TODOS CRs")), SUMIFS('2026'!$K:$K,'2026'!$R:$R,$E$3&$C8,'2026'!$T:$T,M$6), SUMIFS('2026'!$K:$K,'2026'!$N:$N,$E$3&$C8&$E$4,'2026'!$T:$T,M$6)) -> 0 | ... Q8: =IF((AND($E$3="MCS",$E$4="TODOS CRs")), SUMIFS('2026'!$K:$K,'2026'!$R:$R,$E$3&$C8,'2026'!$T:$T,Q$6), SUMIFS('2026'!$K:$K,'2026'!$N:$N,$E$3&$C8&$E$4,'2026'!$T:$T,Q$6)) -> 0 | T8: GAST | U8: =SUMIFS($E$7:$E$40,$B$7:$B$40,T8) -> -6045.55 | V8: =IFERROR(ABS(U8/$U$5),0) -> 0.17997127
B9: REC | C9: REC3 | D9: CPF - Ajuda de custo - Refeição | E9: =SUM(F9:Q9) -> 0 | F9: =IF((AND($E$3="MCS",$E$4="TODOS CRs")), SUMIFS('2026'!$K:$K,'2026'!$R:$R,$E$3&$C9,'2026'!$T:$T,F$6), SUMIFS('2026'!$K:$K,'2026'!$N:$N,$E$3&$C9&$E$4,'2026'!$T:$T,F$6)) -> 0 | G9: =IF((AND($E$3="MCS",$E$4="TODOS CRs")), SUMIFS('2026'!$K:$K,'2026'!$R:$R,$E$3&$C9,'2026'!$T:$T,G$6), SUMIFS('2026'!$K:$K,'2026'!$N:$N,$E$3&$C9&$E$4,'2026'!$T:$T,G$6)) -> 0 | H9: =IF((AND($E$3="MCS",$E$4="TODOS CRs")), SUMIFS('2026'!$K:$K,'2026'!$R:$R,$E$3&$C9,'2026'!$T:$T,H$6), SUMIFS('2026'!$K:$K,'2026'!$N:$N,$E$3&$C9&$E$4,'2026'!$T:$T,H$6)) -> 0 | I9: =IF((AND($E$3="MCS",$E$4="TODOS CRs")), SUMIFS('2026'!$K:$K,'2026'!$R:$R,$E$3&$C9,'2026'!$T:$T,I$6), SUMIFS('2026'!$K:$K,'2026'!$N:$N,$E$3&$C9&$E$4,'2026'!$T:$T,I$6)) -> 0 | J9: =IF((AND($E$3="MCS",$E$4="TODOS CRs")), SUMIFS('2026'!$K:$K,'2026'!$R:$R,$E$3&$C9,'2026'!$T:$T,J$6), SUMIFS('2026'!$K:$K,'2026'!$N:$N,$E$3&$C9&$E$4,'2026'!$T:$T,J$6)) -> 0 | K9: =IF((AND($E$3="MCS",$E$4="TODOS CRs")), SUMIFS('2026'!$K:$K,'2026'!$R:$R,$E$3&$C9,'2026'!$T:$T,K$6), SUMIFS('2026'!$K:$K,'2026'!$N:$N,$E$3&$C9&$E$4,'2026'!$T:$T,K$6)) -> 0 | L9: =IF((AND($E$3="MCS",$E$4="TODOS CRs")), SUMIFS('2026'!$K:$K,'2026'!$R:$R,$E$3&$C9,'2026'!$T:$T,L$6), SUMIFS('2026'!$K:$K,'2026'!$N:$N,$E$3&$C9&$E$4,'2026'!$T:$T,L$6)) -> 0 | M9: =IF((AND($E$3="MCS",$E$4="TODOS CRs")), SUMIFS('2026'!$K:$K,'2026'!$R:$R,$E$3&$C9,'2026'!$T:$T,M$6), SUMIFS('2026'!$K:$K,'2026'!$N:$N,$E$3&$C9&$E$4,'2026'!$T:$T,M$6)) -> 0 | ... Q9: =IF((AND($E$3="MCS",$E$4="TODOS CRs")), SUMIFS('2026'!$K:$K,'2026'!$R:$R,$E$3&$C9,'2026'!$T:$T,Q$6), SUMIFS('2026'!$K:$K,'2026'!$N:$N,$E$3&$C9&$E$4,'2026'!$T:$T,Q$6)) -> 0 | T9: DESP | U9: =SUMIFS($E$7:$E$40,$B$7:$B$40,T9) -> -4028.63 | V9: =IFERROR(ABS(U9/$U$5),0) -> 0.11992915
B10: REC | C10: REC4 | D10: CPF - Transf. Da conta PJ para a conta PF | E10: =SUM(F10:Q10) -> 32740 | F10: =IF((AND($E$3="MCS",$E$4="TODOS CRs")), SUMIFS('2026'!$K:$K,'2026'!$R:$R,$E$3&$C10,'2026'!$T:$T,F$6), SUMIFS('2026'!$K:$K,'2026'!$N:$N,$E$3&$C10&$E$4,'2026'!$T:$T,F$6)) -> 4900 | G10: =IF((AND($E$3="MCS",$E$4="TODOS CRs")), SUMIFS('2026'!$K:$K,'2026'!$R:$R,$E$3&$C10,'2026'!$T:$T,G$6), SUMIFS('2026'!$K:$K,'2026'!$N:$N,$E$3&$C10&$E$4,'2026'!$T:$T,G$6)) -> 5500 | H10: =IF((AND($E$3="MCS",$E$4="TODOS CRs")), SUMIFS('2026'!$K:$K,'2026'!$R:$R,$E$3&$C10,'2026'!$T:$T,H$6), SUMIFS('2026'!$K:$K,'2026'!$N:$N,$E$3&$C10&$E$4,'2026'!$T:$T,H$6)) -> 5040 | I10: =IF((AND($E$3="MCS",$E$4="TODOS CRs")), SUMIFS('2026'!$K:$K,'2026'!$R:$R,$E$3&$C10,'2026'!$T:$T,I$6), SUMIFS('2026'!$K:$K,'2026'!$N:$N,$E$3&$C10&$E$4,'2026'!$T:$T,I$6)) -> 7000 | J10: =IF((AND($E$3="MCS",$E$4="TODOS CRs")), SUMIFS('2026'!$K:$K,'2026'!$R:$R,$E$3&$C10,'2026'!$T:$T,J$6), SUMIFS('2026'!$K:$K,'2026'!$N:$N,$E$3&$C10&$E$4,'2026'!$T:$T,J$6)) -> 6300 | K10: =IF((AND($E$3="MCS",$E$4="TODOS CRs")), SUMIFS('2026'!$K:$K,'2026'!$R:$R,$E$3&$C10,'2026'!$T:$T,K$6), SUMIFS('2026'!$K:$K,'2026'!$N:$N,$E$3&$C10&$E$4,'2026'!$T:$T,K$6)) -> 4000 | L10: =IF((AND($E$3="MCS",$E$4="TODOS CRs")), SUMIFS('2026'!$K:$K,'2026'!$R:$R,$E$3&$C10,'2026'!$T:$T,L$6), SUMIFS('2026'!$K:$K,'2026'!$N:$N,$E$3&$C10&$E$4,'2026'!$T:$T,L$6)) -> 0 | M10: =IF((AND($E$3="MCS",$E$4="TODOS CRs")), SUMIFS('2026'!$K:$K,'2026'!$R:$R,$E$3&$C10,'2026'!$T:$T,M$6), SUMIFS('2026'!$K:$K,'2026'!$N:$N,$E$3&$C10&$E$4,'2026'!$T:$T,M$6)) -> 0 | ... Q10: =IF((AND($E$3="MCS",$E$4="TODOS CRs")), SUMIFS('2026'!$K:$K,'2026'!$R:$R,$E$3&$C10,'2026'!$T:$T,Q$6), SUMIFS('2026'!$K:$K,'2026'!$N:$N,$E$3&$C10&$E$4,'2026'!$T:$T,Q$6)) -> 0 | T10: FIN | U10: =SUMIFS($E$7:$E$40,$B$7:$B$40,T10) -> -2350.3 | V10: =IFERROR(ABS(U10/$U$5),0) -> 0.069966584
